<?xml version="1.0"?>
<robot xmlns:xacro="http://www.ros.org/wiki/xacro" name="robot_name">

<!-- PROPERTY -->
<xacro:property name="base_width" value="0.31"/>
<xacro:property name="base_length" value="0.42"/>
<xacro:property name="base_height" value="0.18"/>

<xacro:property name="wheel_radius" value="0.10"/>
<xacro:property name="wheel_width" value="0.04"/>
<xacro:property name="wheel_ygap" value="0.025"/>
<xacro:property name="wheel_zoff" value="0.01"/>
<xacro:property name="wheel_xoff" value="0.05"/>

<xacro:property name="caster_xoff" value="0.1"/>

<!-- INERTIA -->
<xacro:macro name="box_inertia" params="m w h d">
    <inertial>
        <origin xyz="0.0 0.0 0.0" rpy="${pi/2} 0.0 ${pi/2}"/>
        <mass value="${m}"/>
        <inertia ixx="${(m/12) * (h*h + d*d)}" ixy="0.0" ixz="0.0" iyy="${(m/12) * (w*w + d*d)}" iyz="0.0" izz="${(m/12) * (w*w +h*h)}"/>
    </inertial>
</xacro:macro>

<xacro:macro name="cylinder_inertia" params="m r h">
    <inertial>
        <origin xyz="0.0 0.0 0.0" rpy="${pi/2} 0.0 0"/>
        <mass value="${m}"/>
        <inertia ixx="${(m/12) * (3*r*r + h*h)}" ixy="0.0" ixz="0.0" iyy="${(m/12) * (3*r*r + h*h)}" iyz="0.0" izz="${(m/2) * (r*r)}"/>
    </inertial>
</xacro:macro>

<xacro:macro name="sphere_inertia" params="m r">
    <inertial>
        <mass value="${m}"/>
        <inertia ixx="${(2/5) * m * (r*r)}" ixy="0.0" ixz="0.0" iyy="${(2/5) * m * (r*r)}" iyz="0.0" izz="${(2/5) * m * (r*r)}"/>
    </inertial>
</xacro:macro>

<!-- COLOR -->
<material name="white">
    <color rgba="1 1 1 1"/>
</material>

<material name="blue">
    <color rgba="0 0 1 1"/>
</material>
<material name="red">
    <color rgba="1 0 0 1"/>
</material>
<material name="green">
    <color rgba="0 1 0 1"/>
</material>

<material name="cyan">
    <color rgba="0 1 1 1"/>
</material>
<material name="purple">
    <color rgba="1 0 1 1"/>
</material>


<link name="base_link">
    <visual>
        <origin rpy="0 0 0" xyz="0 0 ${base_height/2}"/>
        <geometry>
            <box size="${base_length} ${base_width} ${base_height} "/>
        </geometry>
        <material name="purple"/>
    </visual>
    <collision>
        <geometry>
            <box size="${base_length} ${base_width} ${base_height} "/>
        </geometry>
        <origin rpy="0 0 0" xyz="0 0 ${base_height/2}"/>
    </collision>
    <xacro:box_inertia m="5" w="${base_width}" d="${base_length}" h="${base_height}" />
</link>

<link name="caster">
    <visual>
        <geometry>
            <sphere radius="${wheel_zoff}"/>
        </geometry>
        <material name="cyan"/>
    </visual>
    <collision>
        <geometry>
            <sphere radius="${wheel_zoff}"/>
        </geometry>
    </collision>
    <xacro:sphere_inertia m="0.5" r="${(wheel_radius+wheel_zoff-(base_height/2))}"/>
</link>

<joint name="caster_joint" type="fixed">
    <parent link="base_link"/>
    <child link="caster"/>
    <origin xyz="${-caster_xoff} 0.0 0.0" rpy="0.0 0.0 0.0"/>
</joint>

<!-- WHEEL -->
<xacro:macro name="wheel" params="prefix x_reflect y_reflect">
    <link name="${prefix}_link">
        <visual name="">
            <origin xyz="0.0 0.0 0.0" rpy="${pi/2} 0.0 0.0"/>
            <geometry>
                <cylinder radius="${wheel_radius}" length="${wheel_width}"/>
            </geometry>
            <material name="green"/>
        </visual>
        <collision>
            <origin xyz="0.0 0.0 0.0" rpy="${pi/2} 0.0 0.0"/>
            <geometry>
                <cylinder radius="${wheel_radius}" length="${wheel_width}"/>
            </geometry>
        </collision>
        <xacro:cylinder_inertia m="0.5" r="${wheel_radius}" h="${wheel_width}"/>
    </link>
    <joint name="${prefix}_joint" type="continuous">
        <parent link="base_link"/>
        <child link="${prefix}_link"/>
        <origin xyz="${-x_reflect*wheel_xoff} ${y_reflect*(base_width/2+wheel_ygap)} ${wheel_radius-wheel_zoff}" rpy="0.0 0.0 0.0"/>
        <axis xyz="0.0 1 0.0"/>
    </joint>
</xacro:macro>

<xacro:wheel prefix="wheel_l" x_reflect="-1" y_reflect="1"/>
<xacro:wheel prefix="wheel_r" x_reflect="-1" y_reflect="-1"/>

</robot>