<?xml version="1.0"?>

<robot xmlns:xacro="http://www.ros.org/wiki/xacro" name="orion">

    <link name="base_footprint" />

    <link name="base_link">
        <inertial>
            <origin xyz="0.0 0.0 0.02" rpy="0.0 0.0 0" />
            <mass value="1.5" />
            <inertia ixx="0.0035705" ixy="0.0" ixz="0.0"
                iyy="0.0057545" iyz="0.0"
                izz="0.008425" />
        </inertial>
        <visual>
            <origin xyz="0.0 0.0 0.02" rpy="0.0 0.0 0" />
            <geometry>
                <mesh filename="package://vehicle_control_software/urdf/meshes/body.stl"/>
                <!-- <box size="0.206 0.158 0.060"/> -->
            </geometry>
            <material name="dark_gray">
                <color rgba="0.4 0.4 0.4 1.0" />
            </material>
        </visual>

        <collision>
            <origin xyz="0.0 0.0 0.02" rpy="0.0 0 0" />
            <geometry>
                <box size="0.206 0.158 0.060"/>
            </geometry>
            <contact_coefficients mu="1" mu2="1" kp="1e+13.0" kd="1.0" />
        </collision>
    </link>

    <link name="left_front_wheel_link">
        <inertial>
            <origin xyz="0 0.0 0.0" rpy="0 0 0.0" />
            <mass value="0.5" />
            <inertia ixx="0.0" ixy="0.0" ixz="0.0" iyy="0.0" iyz="0.0" izz="0.0" />
        </inertial>
        <visual name="">
            <origin xyz="0 0.0 0.0" rpy="0 0 0.0" />
            <geometry>
                <mesh filename="package://vehicle_control_software/urdf/meshes/wheel.stl" />
            </geometry>
            <material name="black">
                <color rgba="0.0 0.0 0.0 1.0" />
            </material>
        </visual>
        <collision>
            <origin xyz="0.0 0.0 0.0" rpy="0 0 0" />
            <geometry>
                <cylinder radius="0.033" length="0.022" />
            </geometry>
        </collision>
    </link>
    <link name="right_front_wheel_link">
        <inertial>
            <origin xyz="0 0.0 0.0" rpy="0 0 0.0" />
            <mass value="0.5" />
            <inertia ixx="0.0" ixy="0.0" ixz="0.0" iyy="0.0" iyz="0.0" izz="0.0" />
        </inertial>
        <visual name="">
            <origin xyz="0 0.0 0.0" rpy="0 0 0.0" />
            <geometry>
                <mesh filename="package://vehicle_control_software/urdf/meshes/wheel.stl" />
            </geometry>
            <material name="black">
                <color rgba="0.0 0.0 0.0 1.0" />
            </material>
        </visual>
        <collision>
            <origin xyz="0.0 0.0 0.0" rpy="0 0 0" />
            <geometry>
                <cylinder radius="0.033" length="0.022" />
            </geometry>
        </collision>
    </link>
    <link name="right_back_wheel_link">
        <inertial>
            <origin xyz="0 0.0 0.0" rpy="0 0 0.0" />
            <mass value="0.5" />
            <inertia ixx="0.0" ixy="0.0" ixz="0.0" iyy="0.0" iyz="0.0" izz="0.0" />
        </inertial>
        <visual name="">
            <origin xyz="0 0.0 0.0" rpy="0 0 0.0" />
            <geometry>
                <mesh filename="package://vehicle_control_software/urdf/meshes/wheel.stl" />
            </geometry>
            <material name="black">
                <color rgba="0.0 0.0 0.0 1.0" />
            </material>
        </visual>
        <collision>
            <origin xyz="0.0 0.0 0.0" rpy="0 0 0" />
            <geometry>
                <cylinder radius="0.033" length="0.022" />
            </geometry>
        </collision>
    </link>
    <link name="left_back_wheel_link">
        <inertial>
            <origin xyz="0 0.0 0.0" rpy="0 0 0.0" />
            <mass value="0.5" />
            <inertia ixx="0.0" ixy="0.0" ixz="0.0" iyy="0.0" iyz="0.0" izz="0.0" />
        </inertial>
        <visual name="">
            <origin xyz="0 0.0 0.0" rpy="0 0 0.0" />
            <geometry>
                <mesh filename="package://vehicle_control_software/urdf/meshes/wheel.stl" />
            </geometry>
            <material name="black">
                <color rgba="0.0 0.0 0.0 1.0" />
            </material>
        </visual>
        <collision>
            <origin xyz="0.0 0.0 0.0" rpy="0 0 0" />
            <geometry>
                <cylinder radius="0.033" length="0.022" />
            </geometry>
        </collision>
    </link>

    <joint name="left_front_wheel_joint" type="continuous">
        <origin xyz="0.06 0.08 0.033" rpy="-1.57 0 0.0" />
        <parent link="base_link" />
        <child link="left_front_wheel_link" />
        <axis xyz="0 0 1" />
    </joint>
    <joint name="right_front_wheel_joint" type="continuous">
        <origin xyz="0.06 -0.08 0.033" rpy="1.57 0 0.0" />
        <parent link="base_link" />
        <child link="right_front_wheel_link" />
        <axis xyz="0 0 1" />
    </joint>
    <joint name="right_back_wheel_joint" type="continuous">
        <origin xyz="-0.07 -0.08 0.033" rpy="1.57 0 0.0" />
        <parent link="base_link" />
        <child link="right_back_wheel_link" />
        <axis xyz="0 0 1" />
    </joint>
    <joint name="left_back_wheel_joint" type="continuous">
        <origin xyz="-0.07 0.08 0.033" rpy="-1.57 0 0.0" />
        <parent link="base_link" />
        <child link="left_back_wheel_link" />
        <axis xyz="0 0 1" />
    </joint>
    <joint name="base_joint" type="fixed">
        <parent link="base_footprint" />
        <child link="base_link" />
        <origin rpy="0 0 0" xyz="0 0 0" />
    </joint>
</robot>